Workbook

Sheet 1 Enero
A2: Activo | C2: Patrimonio neto y pasivo
A3: Terrenos y bienes naturales | B3: 183700 | C3: Capital | D3: 251000
A4: Construcciones | B4: 150000 | C4: Reservas | D4: 40000
A5: Maquinaria | B5: 7000 | C5: Deudas a Largo plazo | D5: 129200
A6: Mobiliario | B6: 10000 | C6: Deudas a Corto plazo | D6: 20000
A7: Clientes | B7: 20300 | C7: Proveedores | D7: 20500
A8: Mercaderías | B8: 11000 | C8: Hacienda Pública, etc | D8: 1300
A9: Tesorería | B9: 80000
A10: TOTAL | B10: =SUM(B3:B9) -> 462000 | C10: TOTAL | D10: =SUM(D3:D9) -> 462000

Sheet Asiento de apertura
A1: PUNTO A: ASIENTO DE APERTURA
A3: Código | B3: Cuenta | C3: Debe | D3: Haber
A4: 210 | B4: Terrenos y bienes naturales | C4: 183700
A5: 211 | B5: Construcciones | C5: 150000
A6: 213 | B6: Maquinaria | C6: 7000
A7: 216 | B7: Mobiliario | C7: 10000
A8: 430 | B8: Clientes | C8: 20300
A9: 300 | B9: Mercaderías | C9: 11000
A10: 57 | B10: Tesorería | C10: 80000
A11: 100 | B11: Capital | D11: 251000
A12: 112 | B12: Reservas | D12: 40000
A13: 170 | B13: Deudas a Largo plazo | D13: 129200
A14: 520 | B14: Deudas a Corto plazo | D14: 20000
A15: 400 | B15: Proveedores | D15: 20500
A16: 470 | B16: Hacienda Pública, etc | D16: 1300
A17: TOTALES | C17: =SUM(C4:C16) -> 462000 | D17: =SUM(D11:D16) -> 462000

Sheet Registros contables
A1: PUNTO B: Registro de las operaciones del ejercicio
A2: 1 | B2: Compra de mercaderías por importe de 25.000 euros, dejando pendiente de pago el 30 por ciento.
A3: Código | B3: Cuenta | C3: Debe | D3: Haber
A4: 600 | B4: Compra de mercaderías | C4: 25000
A5: 401 | B5: Proveedores, efectos comerciales a pagar | D5: =C4*30% -> 7500
A6: 57 | B6: Tesorería | D6: =C4-D5 -> 17500
A8: 2 | B8: Cancela la deuda con proveedores por importe de 20.000 euros.
A9: Código | B9: Cuenta | C9: Debe | D9: Haber
A10: 400 | B10: Proveedores | C10: 20000
A11: 57 | B11: Tesorería | D11: 20000
A13: 3 | B13: Venta de mercaderías por importe de 100.000 euros, quedando pendiente de cobro la tercera parte.
A14: Código | B14: Cuenta | C14: Debe | D14: Haber
A15: 57 | B15: Tesorería | C15: 75000
A16: 430 | B16: Clientes | C16: 25000
A17: 700 | B17: Venta de mercaderías | D17: 100000
A19: 4 | B19: Cobra en efectivo de sus clientes 15.000 euros
A20: Código | B20: Cuenta | C20: Debe | D20: Haber
A21: 57 | B21: Tesorería | C21: 15000
A22: 430 | B22: Clientes | D22: 15000
A24: 5 | B24: Paga en efectivo la nómina de sus empleados que asciende a 36.000 euros.
A25: Código | B25: Cuenta | C25: Debe | D25: Haber
A26: 640 | B26: Sueldos y salarios | C26: 36000
A27: 57 | B27: Tesorería | D27: 36000
A29: 6 | B29: Paga a través de la cuenta corriente bancaria los gastos de electricidad, teléfono y agua que ascienden a 2.100 euros.
A30: Código | B30: Cuenta | C30: Debe | D30: Haber
A31: 628 | B31: Suministros | C31: 2100
A32: 57 | B32: Tesorería | D32: 2100
A34: 7 | B34: Se devengan 2.050 euros de intereses de la deuda que aparece en el balance y que son pagados por la empresa.
A35: Código | B35: Cuenta | C35: Debe | D35: Haber
A36: 528 | B36: Intereses a corto plazo de deudas | C36: 2050
A37: 57 | B37: Tesorería | D37: 2050
A39: 8 | B39: Se paga la totalidad de la deuda a corto plazo.
A40: Código | B40: Cuenta | C40: Debe | D40: Haber
A41: 520 | B41: Deudas a corto plazo | C41: 20000
A42: 57 | B42: Tesorería | D42: 20000
A44: 9 | B44: La cuenta bancaria genera unos intereses de 100 euros
A45: Código | B45: Cuenta | C45: Debe | D45: Haber
A46: 57 | B46: Tesorería | C46: 100
A47: 769 | B47: Otros ingresos financieros | D47: 100
A49: 10 | B49: Compra acciones al contado cuyo coste asciende a 1.100 euros.
...

Sheet SumasSaldos
C1: Sumas | E1: Saldo
A2: Código | B2: Cuenta | C2: Debe | D2: Haber | E2: Deudor | F2: Acreedor
A3: 57 | B3: Tesoreria | C3: ='Registros contables'!C15+'Registros contables'!C21+'Registros contables'!C46 -> 90100 | D3: ='Registros contables'!D6+'Registros contables'!D11+'Registros contables'!D27+'Registros contables'!D32+'Registros contables'!D37+'Registros contables'!D42+'Registros contables'!D52+'Registros contables'!D52 -> 99850 | F3: =D3-C3 -> 9750
A4: 600 | B4: Compra de mercaderías | C4: ='Registros contables'!C4+'Registros contables'!C76 -> 25520 | E4: =C4 -> 25520
A5: 400 | B5: Proveedores | C5: 20000 | D5: ='Registros contables'!D5 -> 7500 | E5: =C5-D5 -> 12500
A6: 430 | B6: Clientes | C6: ='Registros contables'!C16 -> 25000 | D6: ='Registros contables'!D22+'Registros contables'!D82 -> 18000 | E6: =C6-D6 -> 7000
A7: 700 | B7: Venta de mercaderías | D7: ='Registros contables'!D17 -> 100000 | F7: =D7 -> 100000
A8: 769 | B8: Otros ingresos financieros | D8: ='Registros contables'!D47 -> 100 | F8: =D8 -> 100
A9: 250 | B9: Inversiones financieras a largo plazo en instrumentos de patrimonio | C9: ='Registros contables'!C51 -> 1100 | E9: =C9 -> 1100
A10: 520 | B10: Deudas a corto plazo | C10: ='Registros contables'!C41 -> 20000 | D10: ='Registros contables'!D57 -> 20000 | E10: 0 | F10: 0
A11: 250 | B11: Inversiones financieras a largo plazo en instrumentos de patrimonio | C11: ='Registros contables'!C51 -> 1100 | E11: =C11 -> 1100
A12: 170 | B12: Deudas a largo plazo | C12: ='Registros contables'!C56 -> 20000 | E12: =C12 -> 20000
A13: 681 | B13: Amortizacion de inmovilizado material | C13: ='Registros contables'!C61 -> 700 | E13: =C13 -> 700
A14: 281 | B14: Amortización acumulada del inmovilizado material | D14: ='Registros contables'!D62 -> 700 | F14: =D14 -> 700
A15: 629 | B15: Otros servicios | C15: ='Registros contables'!C66 -> 1500 | E15: =C15 -> 1500
A16: 410 | B16: Acreedores por prestaciones de servicios | D16: ='Registros contables'!D67 -> 1500 | F16: =D16 -> 1500
A17: 752 | B17: Ingresos por arrendamientos | D17: ='Registros contables'!D72 -> 12000 | F17: =D17 -> 12000
A18: 610 | B18: Variación de existencias de mercaderías | C18: ='Registros contables'!C86 -> 11000 | D18: ='Registros contables'!D91 -> 4000 | E18: =C18-D18 -> 7000
A19: 640 | B19: Sueldos y salarios | C19: ='Registros contables'!C26 -> 36000 | E19: =C19 -> 36000
A20: 628 | B20: Suministros | C20: ='Registros contables'!C31 -> 2100 | E20: =C20 -> 2100
A21: 528 | B21: Intereses a corto plazo de deudas | C21: ='Registros contables'!C36 -> 2050 | E21: =C21 -> 2050
A22: 440 | B22: Deudores | C22: ='Registros contables'!C71 -> 12000 | E22: =C22 -> 12000
A23: 4009 | B23: Proveedores, facturas pendientes de recibir o formalizar | D23: ='Registros contables'!D77 -> 520 | F23: =D23 -> 520
A24: 4309 | B24: Clientes, facturas pendientes de recibir o formalizar | C24: ='Registros contables'!C81 -> 3000 | E24: =C24 -> 3000
A25: 300 | B25: Mercaderías | C25: ='Registros contables'!C90 -> 4000 | D25: ='Registros contables'!D87 -> 11000 | F25: =D25-C25 -> 7000
A28: TOTAL | C28: =SUM(C3:C27) -> 275170 | D28: =SUM(D3:D27) -> 275170 | E28: =SUM(E3:E27) -> 131570 | F28: =SUM(F3:F27) -> 131570

Sheet Regularizacion
A1: REGULARIZACION
A3: Código | B3: Cuenta | C3: Debe | D3: Haber
A4: 129 | B4: Resultado del ejercicio | C4: =SUM(D5:D13) -> 99970
A5: 600 | B5: Compra de mercaderías | D5: ='Registros contables'!C4+'Registros contables'!C76 -> 25520
A6: 640 | B6: Sueldos y salarios | D6: 36000
A7: 628 | B7: Suministros | D7: 2100
A8: 528 | B8: Intereses a corto plazo de deudas | D8: 2050
A9: 520 | B9: Deudas a corto plazo | D9: 20000
A10: 250 | B10: Inversiones financieras a largo plazo en instrumentos de patrimonio | D10: 1100
A11: 681 | B11: Amortizacion de inmovilizado material | D11: 700
A12: 629 | B12: Otros servicios | D12: 1500
A13: 610 | B13: Variación de existencias de mercaderías | D13: 11000
