Workbook

Sheet Ejer 1
A1: Pedido de Deportes JUANITO
A2: ARTICULOS | B2: PRECIO | D2: Descuentos e IVA | F2: Numeró mínimo para aplicar descuento
A3: Manillar | B3: 200 | D3: Descuento | E3: 0.05 | F3: 100
A4: Frenos | B4: 150 | D4: IVA | E4: 0.21
A5: Ruedas | B5: 500
A6: Horquilla | B6: 800
A7: Cuadro | B7: 1900 | J7: Todas las operaciones deben hacerse de forma que si se insertan 1000 filas se puedan seguir realizando
A8: Cambio | B8: 600 | J8: Cuando pongas una fórmula insertar referencias a celdas. No utilizar los valores de las celdas en las fórmulas
A9: Complementos | B9: 150
A12: Codigo | B12: Descripcion | C12: Unidades | D12: Bruto | E12: Descuento | F12: IVA | G12: Neto | H12: Total
A13: C001 | B13: Manillar | C13: 55 | D13: =VLOOKUP(B13,A3:B9,2,FALSE)*C13 -> 11000 | E13: =IF(C13>=$F$3,D13*$E$3,0) -> 0 | F13: =D13*$E$4 -> 2310 | G13: =D13+F13 -> 13310 | H13: =G13-E13 -> 13310
A14: C002 | B14: Frenos | C14: 115 | D14: =VLOOKUP(B14,A4:B10,2,FALSE)*C14 -> 17250 | E14: =IF(C14>=$F$3,D14*$E$3,0) -> 862.5 | F14: =D14*$E$4 -> 3622.5 | G14: =D14+F14 -> 20872.5 | H14: =G14-E14 -> 20010
A15: C003 | B15: Ruedas | C15: 300 | D15: =VLOOKUP(B15,A5:B11,2,FALSE)*C15 -> 150000 | E15: =IF(C15>=$F$3,D15*$E$3,0) -> 7500 | F15: =D15*$E$4 -> 31500 | G15: =D15+F15 -> 181500 | H15: =G15-E15 -> 174000
A16: C004 | B16: Horquilla | C16: 55 | D16: =VLOOKUP(B16,A6:B12,2,FALSE)*C16 -> 44000 | E16: =IF(C16>=$F$3,D16*$E$3,0) -> 0 | F16: =D16*$E$4 -> 9240 | G16: =D16+F16 -> 53240 | H16: =G16-E16 -> 53240
A17: C005 | B17: Cuadro | C17: 50 | D17: =VLOOKUP(B17,A7:B13,2,FALSE)*C17 -> 95000 | E17: =IF(C17>=$F$3,D17*$E$3,0) -> 0 | F17: =D17*$E$4 -> 19950 | G17: =D17+F17 -> 114950 | H17: =G17-E17 -> 114950
A18: C006 | B18: Cambio | C18: 150 | D18: =VLOOKUP(B18,A8:B14,2,FALSE)*C18 -> 90000 | E18: =IF(C18>=$F$3,D18*$E$3,0) -> 4500 | F18: =D18*$E$4 -> 18900 | G18: =D18+F18 -> 108900 | H18: =G18-E18 -> 104400
A19: C007 | B19: Complementos | C19: 80 | D19: =VLOOKUP(B19,A9:B15,2,FALSE)*C19 -> 12000 | E19: =IF(C19>=$F$3,D19*$E$3,0) -> 0 | F19: =D19*$E$4 -> 2520 | G19: =D19+F19 -> 14520 | H19: =G19-E19 -> 14520
G20: Total | H20: =SUM(H13:H19) -> 494430

Sheet Ejer 2
A1: Tablas de multiplicar con referencias absolutas
A2: X | B2: 1 | C2: 2 | D2: 3 | E2: 4 | F2: 5 | G2: 6 | H2: 7 | I2: 8 | J2: 9
A3: 1 | B3: =B$2*$A3 -> 1 | C3: =C$2*$A3 -> 2 | D3: =D$2*$A3 -> 3 | E3: =E$2*$A3 -> 4 | F3: =F$2*$A3 -> 5 | G3: =G$2*$A3 -> 6 | H3: =H$2*$A3 -> 7 | I3: =I$2*$A3 -> 8 | J3: =J$2*$A3 -> 9
A4: 2 | B4: =B$2*$A4 -> 2 | C4: =C$2*$A4 -> 4 | D4: =D$2*$A4 -> 6 | E4: =E$2*$A4 -> 8 | F4: =F$2*$A4 -> 10 | G4: =G$2*$A4 -> 12 | H4: =H$2*$A4 -> 14 | I4: =I$2*$A4 -> 16 | J4: =J$2*$A4 -> 18
A5: 3 | B5: =B$2*$A5 -> 3 | C5: =C$2*$A5 -> 6 | D5: =D$2*$A5 -> 9 | E5: =E$2*$A5 -> 12 | F5: =F$2*$A5 -> 15 | G5: =G$2*$A5 -> 18 | H5: =H$2*$A5 -> 21 | I5: =I$2*$A5 -> 24 | J5: =J$2*$A5 -> 27
A6: 4 | B6: =B$2*$A6 -> 4 | C6: =C$2*$A6 -> 8 | D6: =D$2*$A6 -> 12 | E6: =E$2*$A6 -> 16 | F6: =F$2*$A6 -> 20 | G6: =G$2*$A6 -> 24 | H6: =H$2*$A6 -> 28 | I6: =I$2*$A6 -> 32 | J6: =J$2*$A6 -> 36
A7: 5 | B7: =B$2*$A7 -> 5 | C7: =C$2*$A7 -> 10 | D7: =D$2*$A7 -> 15 | E7: =E$2*$A7 -> 20 | F7: =F$2*$A7 -> 25 | G7: =G$2*$A7 -> 30 | H7: =H$2*$A7 -> 35 | I7: =I$2*$A7 -> 40 | J7: =J$2*$A7 -> 45
A8: 6 | B8: =B$2*$A8 -> 6 | C8: =C$2*$A8 -> 12 | D8: =D$2*$A8 -> 18 | E8: =E$2*$A8 -> 24 | F8: =F$2*$A8 -> 30 | G8: =G$2*$A8 -> 36 | H8: =H$2*$A8 -> 42 | I8: =I$2*$A8 -> 48 | J8: =J$2*$A8 -> 54
A9: 7 | B9: =B$2*$A9 -> 7 | C9: =C$2*$A9 -> 14 | D9: =D$2*$A9 -> 21 | E9: =E$2*$A9 -> 28 | F9: =F$2*$A9 -> 35 | G9: =G$2*$A9 -> 42 | H9: =H$2*$A9 -> 49 | I9: =I$2*$A9 -> 56 | J9: =J$2*$A9 -> 63
A10: 8 | B10: =B$2*$A10 -> 8 | C10: =C$2*$A10 -> 16 | D10: =D$2*$A10 -> 24 | E10: =E$2*$A10 -> 32 | F10: =F$2*$A10 -> 40 | G10: =G$2*$A10 -> 48 | H10: =H$2*$A10 -> 56 | I10: =I$2*$A10 -> 64 | J10: =J$2*$A10 -> 72
A11: 9 | B11: =B$2*$A11 -> 9 | C11: =C$2*$A11 -> 18 | D11: =D$2*$A11 -> 27 | E11: =E$2*$A11 -> 36 | F11: =F$2*$A11 -> 45 | G11: =G$2*$A11 -> 54 | H11: =H$2*$A11 -> 63 | I11: =I$2*$A11 -> 72 | J11: =J$2*$A11 -> 81
B13: En este ejercicio se trata de usar las las referencias absolutas en las hojas de cálculo
B14: Debes rellenar la celda B3 con referencias a las celdas B2 y A3 de forma que al arrastrarla tanto a derechas como hacía abajo se reproduzcan las tablas de multiplicar
B15: Arrastar la celda B3 hacia la derecha y hacia abajo hasta completar las tablas de multiplicar

Sheet Ejer 3
H1: Probeta de sección cuadrada
A2: Deformación e: | C2: e = Dl/l0 | E2: 1 m = | F2: 1000 | G2: mm | H2: Longitud de la muestra | J2: 500 | K2: mm
A3: Tensión s: | C3: s = F/A0 | E3: g = | F3: 9.8 | G3: m/s2 | H3: Lado de la sección | J3: 5 | K3: mm
H4: Sección de la muestra | J4: =$J$3*$J$3 -> 25 | K4: mm2
A6: Fuerza F (kgf) | B6: Alargamiento Dl (m) | C6: Fuerza F (N) | D6: Alargamiento Dl (mm) | E6: Deformación e | F6: Tensión s (N/mm2=MPa)
A7: 0 | B7: 0 | C7: =A7*$F$3 -> 0 | D7: =B7*$F$2 -> 0 | E7: =D7/$J$2 -> 0 | F7: =C7/$J$4 -> 0
A8: 500 | B8: 0.0003 | C8: =A8*$F$3 -> 4900 | D8: =B8*$F$2 -> 0.3 | E8: =D8/$J$2 -> 0.0006 | F8: =C8/$J$4 -> 196
A9: 1000 | B9: 0.0006 | C9: =A9*$F$3 -> 9800 | D9: =B9*$F$2 -> 0.6 | E9: =D9/$J$2 -> 0.0012 | F9: =C9/$J$4 -> 392
A10: 2000 | B10: 0.0012 | C10: =A10*$F$3 -> 19600 | D10: =B10*$F$2 -> 1.2 | E10: =D10/$J$2 -> 0.0024 | F10: =C10/$J$4 -> 784
A11: 2400 | B11: 0.0017 | C11: =A11*$F$3 -> 23520 | D11: =B11*$F$2 -> 1.7 | E11: =D11/$J$2 -> 0.0034 | F11: =C11/$J$4 -> 940.8
A12: 3000 | B12: 0.0043 | C12: =A12*$F$3 -> 29400 | D12: =B12*$F$2 -> 4.3 | E12: =D12/$J$2 -> 0.0086 | F12: =C12/$J$4 -> 1176
A13: 3500 | B13: 0.012 | C13: =A13*$F$3 -> 34300 | D13: =B13*$F$2 -> 12 | E13: =D13/$J$2 -> 0.024 | F13: =C13/$J$4 -> 1372
A14: 3550 | B14: 0.0155 | C14: =A14*$F$3 -> 34790 | D14: =B14*$F$2 -> 15.5 | E14: =D14/$J$2 -> 0.031 | F14: =C14/$J$4 -> 1391.6
A15: 3300 | B15: 0.019 | C15: =A15*$F$3 -> 32340 | D15: =B15*$F$2 -> 19 | E15: =D15/$J$2 -> 0.038 | F15: =C15/$J$4 -> 1293.6

Sheet Ejer 4
A1: Alumno | B1: AA1 | C1: AA2 | D1: AEC 1 | E1: AEC2 2 | F1: control 1 | G1: control 2 | H1: examen | I1: Nota curso
A2: Alumno 1 | B2: 8 | I2: =(AVERAGE(--B2,--C2)*'Porcentaje notas'!$B$1)+(AVERAGE(--D2,--E2)*'Porcentaje notas'!$B$2)+(AVERAGE(--F2,--G2)*'Porcentaje notas'!$B$3)+(--H2*'Porcentaje notas'!$B$4) -> 0.4
A3: Alumno 2 | C3: 8 | F3: 2 | G3: 2 | H3: 5 | I3: =(AVERAGE(--B3,--C3)*'Porcentaje notas'!$B$1)+(AVERAGE(--D3,--E3)*'Porcentaje notas'!$B$2)+(AVERAGE(--F3,--G3)*'Porcentaje notas'!$B$3)+(--H3*'Porcentaje notas'!$B$4) -> 3.8
A4: Alumno 3 | B4: 5 | C4: 6 | D4: 0.8 | E4: 3 | G4: 0.5 | H4: 5 | I4: =(AVERAGE(--B4,--C4)*'Porcentaje notas'!$B$1)+(AVERAGE(--D4,--E4)*'Porcentaje notas'!$B$2)+(AVERAGE(--F4,--G4)*'Porcentaje notas'!$B$3)+(--H4*'Porcentaje notas'!$B$4) -> 3.79
A5: Alumno 4 | B5: 5 | D5: 6.5 | I5: =(AVERAGE(--B5,--C5)*'Porcentaje notas'!$B$1)+(AVERAGE(--D5,--E5)*'Porcentaje notas'!$B$2)+(AVERAGE(--F5,--G5)*'Porcentaje notas'!$B$3)+(--H5*'Porcentaje notas'!$B$4) -> 0.575
A6: Alumno 5 | B6: 5 | C6: 6 | F6: 8 | I6: =(AVERAGE(--B6,--C6)*'Porcentaje notas'!$B$1)+(AVERAGE(--D6,--E6)*'Porcentaje notas'!$B$2)+(AVERAGE(--F6,--G6)*'Porcentaje notas'!$B$3)+(--H6*'Porcentaje notas'!$B$4) -> 1.35
A7: Alumno 6 | B7: 8 | C7: 4 | D7: 8 | E7: 8 | F7: 8 | G7: 7 | H7: 9 | I7: =(AVERAGE(--B7,--C7)*'Porcentaje notas'!$B$1)+(AVERAGE(--D7,--E7)*'Porcentaje notas'!$B$2)+(AVERAGE(--F7,--G7)*'Porcentaje notas'!$B$3)+(--H7*'Porcentaje notas'!$B$4) -> 8.3
A8: Alumno 7 | B8: 5.5 | C8: 6.5 | D8: 3.25 | E8: 9 | I8: =(AVERAGE(--B8,--C8)*'Porcentaje notas'!$B$1)+(AVERAGE(--D8,--E8)*'Porcentaje notas'!$B$2)+(AVERAGE(--F8,--G8)*'Porcentaje notas'!$B$3)+(--H8*'Porcentaje notas'!$B$4) -> 1.2125
A9: Alumno 8 | B9: 6.5 | C9: 7 | F9: 5 | G9: 0.5 | H9: 5.6 | I9: =(AVERAGE(--B9,--C9)*'Porcentaje notas'!$B$1)+(AVERAGE(--D9,--E9)*'Porcentaje notas'!$B$2)+(AVERAGE(--F9,--G9)*'Porcentaje notas'!$B$3)+(--H9*'Porcentaje notas'!$B$4) -> 4.585
A10: Alumno 9 | B10: 0 | C10: 1 | D10: 9 | E10: 2 | G10: 0.6 | H10: 5 | I10: =(AVERAGE(--B10,--C10)*'Porcentaje notas'!$B$1)+(AVERAGE(--D10,--E10)*'Porcentaje notas'!$B$2)+(AVERAGE(--F10,--G10)*'Porcentaje notas'!$B$3)+(--H10*'Porcentaje notas'!$B$4) -> 3.66
A11: Alumno 10 | B11: 10 | C11: 10 | D11: 10 | E11: 10 | F11: 10 | G11: 10 | H11: 10 | I11: =(AVERAGE(--B11,--C11)*'Porcentaje notas'!$B$1)+(AVERAGE(--D11,--E11)*'Porcentaje notas'!$B$2)+(AVERAGE(--F11,--G11)*'Porcentaje notas'!$B$3)+(--H11*'Porcentaje notas'!$B$4) -> 10
A12: Alumno 11 | B12: 0 | C12: 1 | I12: =(AVERAGE(--B12,--C12)*'Porcentaje notas'!$B$1)+(AVERAGE(--D12,--E12)*'Porcentaje notas'!$B$2)+(AVERAGE(--F12,--G12)*'Porcentaje notas'!$B$3)+(--H12*'Porcentaje notas'!$B$4) -> 0.05
A13: Alumno 12 | B13: 3.3 | C13: 4 | E13: 2.6 | G13: 1.3 | H13: 5 | I13: =(AVERAGE(--B13,--C13)*'Porcentaje notas'!$B$1)+(AVERAGE(--D13,--E13)*'Porcentaje notas'!$B$2)+(AVERAGE(--F13,--G13)*'Porcentaje notas'!$B$3)+(--H13*'Porcentaje notas'!$B$4) -> 3.625
A14: Alumno 13 | B14: 3.3 | C14: 4.3 | F14: 7 | H14: 9 | I14: =(AVERAGE(--B14,--C14)*'Porcentaje notas'!$B$1)+(AVERAGE(--D14,--E14)*'Porcentaje notas'!$B$2)+(AVERAGE(--F14,--G14)*'Porcentaje notas'!$B$3)+(--H14*'Porcentaje notas'!$B$4) -> 6.48
A15: Alumno 14 | B15: 8.8 | C15: 9 | D15: 5 | E15: 8 | G15: 0.8 | H15: 9 | I15: =(AVERAGE(--B15,--C15)*'Porcentaje notas'!$B$1)+(AVERAGE(--D15,--E15)*'Porcentaje notas'!$B$2)+(AVERAGE(--F15,--G15)*'Porcentaje notas'!$B$3)+(--H15*'Porcentaje notas'!$B$4) -> 7.02
A16: Alumno 15 | B16: 8.8 | C16: 9 | D16: 2.6 | H16: 5 | I16: =(AVERAGE(--B16,--C16)*'Porcentaje notas'!$B$1)+(AVERAGE(--D16,--E16)*'Porcentaje notas'!$B$2)+(AVERAGE(--F16,--G16)*'Porcentaje notas'!$B$3)+(--H16*'Porcentaje notas'!$B$4) -> 4.02
A17: Alumno 16 | B17: 6.5 | C17: 7 | E17: 8 | G17: 2.3 | H17: 2.8 | I17: =(AVERAGE(--B17,--C17)*'Porcentaje notas'!$B$1)+(AVERAGE(--D17,--E17)*'Porcentaje notas'!$B$2)+(AVERAGE(--F17,--G17)*'Porcentaje notas'!$B$3)+(--H17*'Porcentaje notas'!$B$4) -> 2.985
A18: Alumno 17 | B18: 4.3 | C18: 5.3 | D18: 8 | F18: 8 | H18: 9 | I18: =(AVERAGE(--B18,--C18)*'Porcentaje notas'!$B$1)+(AVERAGE(--D18,--E18)*'Porcentaje notas'!$B$2)+(AVERAGE(--F18,--G18)*'Porcentaje notas'!$B$3)+(--H18*'Porcentaje notas'!$B$4) -> 7.08
A19: Alumno 18 | B19: 6.8 | C19: 7 | D19: 0.5 | E19: 0 | H19: 6.5 | I19: =(AVERAGE(--B19,--C19)*'Porcentaje notas'!$B$1)+(AVERAGE(--D19,--E19)*'Porcentaje notas'!$B$2)+(AVERAGE(--F19,--G19)*'Porcentaje notas'!$B$3)+(--H19*'Porcentaje notas'!$B$4) -> 4.615
A20: Alumno 19 | B20: 6.8 | C20: 7 | E20: 8 | F20: 2 | G20: 8 | I20: =(AVERAGE(--B20,--C20)*'Porcentaje notas'!$B$1)+(AVERAGE(--D20,--E20)*'Porcentaje notas'!$B$2)+(AVERAGE(--F20,--G20)*'Porcentaje notas'!$B$3)+(--H20*'Porcentaje notas'!$B$4) -> 2.09
A21: Alumno 20 | B21: 6.8 | C21: 8 | D21: 8 | E21: 3 | F21: 2 | G21: 0 | I21: =(AVERAGE(--B21,--C21)*'Porcentaje notas'!$B$1)+(AVERAGE(--D21,--E21)*'Porcentaje notas'!$B$2)+(AVERAGE(--F21,--G21)*'Porcentaje notas'!$B$3)+(--H21*'Porcentaje notas'!$B$4) -> 1.49
A22: Alumno 21 | B22: 6.5 | C22: 7.5 | I22: =(AVERAGE(--B22,--C22)*'Porcentaje notas'!$B$1)+(AVERAGE(--D22,--E22)*'Porcentaje notas'!$B$2)+(AVERAGE(--F22,--G22)*'Porcentaje notas'!$B$3)+(--H22*'Porcentaje notas'!$B$4) -> 0.7
A23: Alumno 22 | B23: 5 | C23: 6 | D23: 7 | E23: 7 | F23: 7 | H23: 9.1 | I23: =(AVERAGE(--B23,--C23)*'Porcentaje notas'!$B$1)+(AVERAGE(--D23,--E23)*'Porcentaje notas'!$B$2)+(AVERAGE(--F23,--G23)*'Porcentaje notas'!$B$3)+(--H23*'Porcentaje notas'!$B$4) -> 7.41
A24: Alumno 23 | B24: 8.9 | C24: 9 | D24: 2.4 | F24: 9 | H24: 7 | I24: =(AVERAGE(--B24,--C24)*'Porcentaje notas'!$B$1)+(AVERAGE(--D24,--E24)*'Porcentaje notas'!$B$2)+(AVERAGE(--F24,--G24)*'Porcentaje notas'!$B$3)+(--H24*'Porcentaje notas'!$B$4) -> 6.115
A25: Alumno 24 | B25: 8.9 | C25: 9 | D25: 8 | E25: 4 | F25: 9 | G25: 8 | H25: 9 | I25: =(AVERAGE(--B25,--C25)*'Porcentaje notas'!$B$1)+(AVERAGE(--D25,--E25)*'Porcentaje notas'!$B$2)+(AVERAGE(--F25,--G25)*'Porcentaje notas'!$B$3)+(--H25*'Porcentaje notas'!$B$4) -> 8.595
A26: Alumno 25 | B26: 9 | C26: 10 | F26: 7 | H26: 0 | I26: =(AVERAGE(--B26,--C26)*'Porcentaje notas'!$B$1)+(AVERAGE(--D26,--E26)*'Porcentaje notas'!$B$2)+(AVERAGE(--F26,--G26)*'Porcentaje notas'!$B$3)+(--H26*'Porcentaje notas'!$B$4) -> 1.65
A27: Alumno 26 | B27: 5.2 | C27: 6.2 | D27: 0.2 | E27: 7 | H27: 6.5 | I27: =(AVERAGE(--B27,--C27)*'Porcentaje notas'!$B$1)+(AVERAGE(--D27,--E27)*'Porcentaje notas'!$B$2)+(AVERAGE(--F27,--G27)*'Porcentaje notas'!$B$3)+(--H27*'Porcentaje notas'!$B$4) -> 4.83
A28: Alumno 27 | B28: 5.3 | C28: 6 | D28: 0.6 | G28: 0.55 | H28: 7.5 | I28: =(AVERAGE(--B28,--C28)*'Porcentaje notas'!$B$1)+(AVERAGE(--D28,--E28)*'Porcentaje notas'!$B$2)+(AVERAGE(--F28,--G28)*'Porcentaje notas'!$B$3)+(--H28*'Porcentaje notas'!$B$4) -> 5.15
A29: Alumno 28 | B29: 9 | C29: 10 | D29: 2.4 | F29: 8 | G29: 5.55 | H29: 7 | I29: =(AVERAGE(--B29,--C29)*'Porcentaje notas'!$B$1)+(AVERAGE(--D29,--E29)*'Porcentaje notas'!$B$2)+(AVERAGE(--F29,--G29)*'Porcentaje notas'!$B$3)+(--H29*'Porcentaje notas'!$B$4) -> 6.625
A30: Alumno 29 | F30: 4 | H30: 0 | I30: =(AVERAGE(--B30,--C30)*'Porcentaje notas'!$B$1)+(AVERAGE(--D30,--E30)*'Porcentaje notas'!$B$2)+(AVERAGE(--F30,--G30)*'Porcentaje notas'!$B$3)+(--H30*'Porcentaje notas'!$B$4) -> 0.4
A31: Alumno 30 | C31: 4 | E31: 4 | H31: 6.5 | I31: =(AVERAGE(--B31,--C31)*'Porcentaje notas'!$B$1)+(AVERAGE(--D31,--E31)*'Porcentaje notas'!$B$2)+(AVERAGE(--F31,--G31)*'Porcentaje notas'!$B$3)+(--H31*'Porcentaje notas'!$B$4) -> 4.3
A32: Alumno 31 | B32: 7 | C32: 8 | D32: 4.2 | E32: 5.6 | G32: 6.5 | H32: 8.8 | I32: =(AVERAGE(--B32,--C32)*'Porcentaje notas'!$B$1)+(AVERAGE(--D32,--E32)*'Porcentaje notas'!$B$2)+(AVERAGE(--F32,--G32)*'Porcentaje notas'!$B$3)+(--H32*'Porcentaje notas'!$B$4) -> 7.17
A33: Alumno 32 | H33: 6.5 | I33: =(AVERAGE(--B33,--C33)*'Porcentaje notas'!$B$1)+(AVERAGE(--D33,--E33)*'Porcentaje notas'!$B$2)+(AVERAGE(--F33,--G33)*'Porcentaje notas'!$B$3)+(--H33*'Porcentaje notas'!$B$4) -> 3.9
A34: Alumno 33 | B34: 5 | C34: 5 | D34: 4 | E34: 6.3 | F34: 7 | G34: 4.3 | H34: 7 | I34: =(AVERAGE(--B34,--C34)*'Porcentaje notas'!$B$1)+(AVERAGE(--D34,--E34)*'Porcentaje notas'!$B$2)+(AVERAGE(--F34,--G34)*'Porcentaje notas'!$B$3)+(--H34*'Porcentaje notas'!$B$4) -> 6.345
A35: Alumno 34 | B35: 3 | C35: 3 | D35: 0.75 | E35: 0 | G35: 2.5 | H35: 6.8 | I35: =(AVERAGE(--B35,--C35)*'Porcentaje notas'!$B$1)+(AVERAGE(--D35,--E35)*'Porcentaje notas'!$B$2)+(AVERAGE(--F35,--G35)*'Porcentaje notas'!$B$3)+(--H35*'Porcentaje notas'!$B$4) -> 4.6675
A36: Alumno 35 | B36: 7 | C36: 8 | D36: 3 | E36: 5.2 | G36: 8 | H36: 6.8 | I36: =(AVERAGE(--B36,--C36)*'Porcentaje notas'!$B$1)+(AVERAGE(--D36,--E36)*'Porcentaje notas'!$B$2)+(AVERAGE(--F36,--G36)*'Porcentaje notas'!$B$3)+(--H36*'Porcentaje notas'!$B$4) -> 6.04
A37: Alumno 36 | H37: 4.3 | I37: =(AVERAGE(--B37,--C37)*'Porcentaje notas'!$B$1)+(AVERAGE(--D37,--E37)*'Porcentaje notas'!$B$2)+(AVERAGE(--F37,--G37)*'Porcentaje notas'!$B$3)+(--H37*'Porcentaje notas'!$B$4) -> 2.58
A38: Alumno 37 | B38: 5 | D38: 4.2 | H38: 2.25 | I38: =(AVERAGE(--B38,--C38)*'Porcentaje notas'!$B$1)+(AVERAGE(--D38,--E38)*'Porcentaje notas'!$B$2)+(AVERAGE(--F38,--G38)*'Porcentaje notas'!$B$3)+(--H38*'Porcentaje notas'!$B$4) -> 1.81
A39: Alumno 38 | B39: 2.8 | C39: 3.8 | F39: 8 | G39: 8 | H39: 6.5 | I39: =(AVERAGE(--B39,--C39)*'Porcentaje notas'!$B$1)+(AVERAGE(--D39,--E39)*'Porcentaje notas'!$B$2)+(AVERAGE(--F39,--G39)*'Porcentaje notas'!$B$3)+(--H39*'Porcentaje notas'!$B$4) -> 5.83
A40: Alumno 39 | B40: 5.5 | C40: 5 | D40: 0.25 | E40: 7 | H40: 5 | I40: =(AVERAGE(--B40,--C40)*'Porcentaje notas'!$B$1)+(AVERAGE(--D40,--E40)*'Porcentaje notas'!$B$2)+(AVERAGE(--F40,--G40)*'Porcentaje notas'!$B$3)+(--H40*'Porcentaje notas'!$B$4) -> 3.8875
...

Sheet Porcentaje notas
A1: AA | B1: 0.1
A2: Controles | B2: 0.1
A3: AEC | B3: 0.2
A4: Examen | B4: 0.6
