Workbook

Sheet SUPUESTO A.1
A9: Código | B9: Cuenta | C9: Debe | D9: Haber
A10: 572 | B10: Tesoreria | C10: 30000
A11: 543 | B11: Créditos a corto plazo por enajenación de inmovilizado | C11: 70000
A12: 281 | B12: Amortización acumulada del inmovilizado material | C12: 50000
A13: 671 | B13: Pérdidas procedentes de inmovilizado material | C13: 150000
A14: 210 | B14: Terrenos y bienes naturales | D14: 100000
A15: 211 | B15: Construcciones | D15: 200000

Sheet SUPUESTO A.2
A8: Año de cuota | B8: 1 | D8: Código | E8: Cuenta | F8: Debe | G8: Haber
A9: Duración del préstamo | B9: 10 | D9: 213 | E9: Maquinaria | F9: 100000
A10: Base amortizable | B10: =100000-0 -> 100000 | D10: 572 | E10: Bancos | G10: 100000
A11: Cuota annual | B11: =(2*B8)/(B9*(B9+1))*B10 -> 1818.1818 | D11: 681 | E11: Amortización del inmovilizado material | F11: =B11 -> 1818.1818
D12: 281 | E12: Amortización acumulada del inmovilizado material | G12: =B11 -> 1818.1818

Sheet SUPUESTO A.3
B10: 31/12/20X6
A11: Código | B11: Cuenta | C11: Debe | D11: Haber
A12: 231 | B12: Construcciones en curso | C12: 200000
A13: 731 | B13: Trabajos realizados para el inmovilizado materia | D13: 200000
B15: 01/06/20X7
A16: Código | B16: Cuenta | C16: Debe | D16: Haber
A17: 211 | B17: Construcciones | C17: 300000
A18: 231 | B18: Construcciones en curso | D18: 200000
A19: 731 | B19: Trabajos realizados para el inmovilizado material | D19: 100000
B21: 31/12/20X7
A22: Código | B22: Cuenta | C22: Debe | D22: Haber | F22: Base amortizacion | G22: 300000
A23: 681 | B23: Amortización del inmovilizado material | C23: =G23 -> 12000 | F23: Amortizacion annual | G23: =G22*4% -> 12000
A24: 281 | B24: Amortización acumulada del inmovilizado material | D24: =G23 -> 12000

Sheet SUPUESTO A.4
B8: 15/09/20X7
A9: Código | B9: Cuenta | C9: Debe | D9: Haber
A10: 431 | B10: Clientes, efectos comerciales a cobrar | C10: 2100
A11: 700 | B11: Venta de mercaderías | D11: 2100
B13: 01/11/20X7
A14: Código | B14: Cuenta | C14: Debe | D14: Haber
A15: 572 | B15: Banco | C15: 1050
A16: 431 | B16: Clientes, efectos comerciales a cobrar | D16: 1050
B18: 01/12/20X7
A19: Código | B19: Cuenta | C19: Debe | D19: Haber
A20: 572 | B20: Banco | C20: 1050
A21: 431 | B21: Clientes, efectos comerciales a cobrar | D21: 1050

Sheet SUPUESTO A.5
A19: Código | B19: Cuenta | C19: Debe | D19: Haber
A20: 600 | B20: Compra de mercaderías | C20: 9600
A21: 401 | B21: Proveedores, efectos comerciales a cobrar | D21: 9600

Sheet Parte B. Asiento de apertura
A1: Código | B1: Cuenta | C1: Debe | D1: Haber
A2: 210 | B2: Terrenos y bienes naturales | C2: 800000
A3: 216 | B3: Mobiliario | C3: 200000
A4: 217 | B4: Equipos informáticos | C4: 150000
A5: 300 | B5: Mercaderías | C5: 20000
A6: 430 | B6: Clientes | C6: 35000
A7: 431 | B7: Clientes, efectos comerciales a cobrar | C7: 50000
A8: 540 | B8: Inversiones financieras temporales en instrumentos de patrimonio | C8: 25100
A9: 570 | B9: Caja | C9: 700000
A10: 572 | B10: Bancos | C10: 1000000
A11: 100 | B11: Capital Social | D11: 1000000
A12: 11 | B12: Reservas | D12: 255000
A13: 130 | B13: Subvenciones oficiales de capital | D13: 200100
A14: 171 | B14: Deudas a largo plazo | D14: 1050000
A15: 521 | B15: Deudas a corto plazo | D15: 20000
A16: 400 | B16: Proveedores | D16: 200000
A17: 410 | B17: Acreedores por prestaciones de servicio | D17: 255000
B18: TOTAL | C18: =SUM(C2:C17) -> 2980100 | D18: =SUM(D11:D17) -> 2980100

Sheet Parte B. Contabilidad 20X1
A5: Código | B5: Cuenta | C5: Debe | D5: Haber
A6: 600 | B6: Compra de mercaderías | C6: 29000
A7: 472 | B7: HP, IVA Soportado | C7: 6090
A8: 570 | B8: Caja | D8: 17545
A9: 400 | B9: Proveedores | D9: 17545
A14: Código | B14: Cuenta | C14: Debe | D14: Haber
A15: 600 | B15: Compra de mercaderías | C15: 5850
A16: 472 | B16: HP, IVA Soportado | C16: =C15*21% -> 1228.5
A17: 570 | B17: Caja | D17: =C15+C16 -> 7078.5
A30: Código | B30: Cuenta | C30: Debe | D30: Haber
A31: 640 | B31: Sueldos | C31: 102000
A32: 642 | B32: Seguridad Social | C32: 30000
A33: 4751 | B33: HP | D33: 2000
A34: 476 | B34: Seguridad Social, acreedores | D34: 35000
A35: 572 | B35: Bancos | D35: 95000
A40: Código | B40: Cuenta | C40: Debe | D40: Haber
A41: 650 | B41: Pérdidas de créditos comerciales incobrables | C41: 35000
A42: 430 | B42: Clientes | D42: 35000
A47: Código | B47: Cuenta | C47: Debe | D47: Haber
A48: 628 | B48: Suministros | C48: 700
A49: 472 | B49: HP, IVA Soportado | C49: =C48*21% -> 147
A50: 572 | B50: Bancos | D50: =C49+C48 -> 847
A55: Código | B55: Cuenta | C55: Debe | D55: Haber
A56: 430 | B56: Clientes | C56: 8591
A57: 700 | B57: Ventas de mercaderías | D57: 7100
A58: 477 | B58: HP, IVA repercutido | D58: =D57*21% -> 1491
A67: Código | B67: Cuenta | C67: Debe | D67: Haber
A68: 572 | B68: Bancos | C68: 4295.5
A69: 4310 | B69: Efectos comerciales en cartera | C69: 4295.5
A70: 430 | B70: Clientes | D70: 8591
A72: Código | B72: Cuenta | C72: Debe | D72: Haber
A73: 4312 | B73: Efectos comerciales en gestión de cobro | C73: =C68/4 -> 1073.875
A74: 4310 | B74: Efectos comerciales en cartera | D74: =C73 -> 1073.875
A76: Código | B76: Cuenta | C76: Debe | D76: Haber
A77: 4311 | B77: Efectos comerciales descontados | C77: =C68-C73 -> 3221.625
A78: 4310 | B78: Efectos comerciales en cartera | D78: =C77 -> 3221.625
A80: Código | B80: Cuenta | C80: Debe | D80: Haber
A81: 572 | B81: Bancos | C81: =D83-C82 -> 3157.1925
A82: 665 | B82: Intereses por descuento de efectos y factoring | C82: =C77*2% -> 64.4325
A83: 5208 | B83: Deudas por efectos descontados | D83: =D78 -> 3221.625
...

Sheet Parte B. Asiento reg.
A2: Ingresos
A3: 700 | B3: Venta de mercaderías | C3: =SUMIF('Parte B. Contabilidad 20X1'!A1:A244,"="&A3,'Parte B. Contabilidad 20X1'!D1:D244) -> 2007100
A4: 769 | B4: Otros ingresos financieros | C4: =SUMIF('Parte B. Contabilidad 20X1'!A2:A245,"="&A4,'Parte B. Contabilidad 20X1'!D2:D245) -> 1000
A5: 771 | B5: Beneficios procedentes del Inmovilizado material | C5: =SUMIF('Parte B. Contabilidad 20X1'!A3:A246,"="&A5,'Parte B. Contabilidad 20X1'!D3:D246) -> 37000
A6: Total | C6: =SUM(C3:C5) -> 2045100
A7: Gastos
A8: 600 | B8: Compra de mercaderías | C8: =SUMIF('Parte B. Contabilidad 20X1'!A1:A249,"="&A8,'Parte B. Contabilidad 20X1'!C1:C249) -> 139850
A9: 610 | B9: Variación de existencias de mercaderías | C9: =SUMIF('Parte B. Contabilidad 20X1'!A2:A250,"="&A9,'Parte B. Contabilidad 20X1'!C2:C250)-SUMIF('Parte B. Contabilidad 20X1'!A1:A244,"="&'Parte B. Asiento reg.'!A9,'Parte B. Contabilidad 20X1'!D1:D244) -> -4570
A10: 623 | B10: Servicios de profesionales independientes | C10: =SUMIF('Parte B. Contabilidad 20X1'!A3:A251,"="&A10,'Parte B. Contabilidad 20X1'!C3:C251)-SUMIF('Parte B. Contabilidad 20X1'!A2:A245,"="&'Parte B. Asiento reg.'!A10,'Parte B. Contabilidad 20X1'!D2:D245) -> 6000
A11: 626 | B11: Servicios bancarios y similares | C11: =SUMIF('Parte B. Contabilidad 20X1'!A4:A252,"="&A11,'Parte B. Contabilidad 20X1'!C4:C252)-SUMIF('Parte B. Contabilidad 20X1'!A3:A246,"="&'Parte B. Asiento reg.'!A11,'Parte B. Contabilidad 20X1'!D3:D246) -> 280
A12: 628 | B12: Suministros | C12: =SUMIF('Parte B. Contabilidad 20X1'!A5:A253,"="&A12,'Parte B. Contabilidad 20X1'!C5:C253)-SUMIF('Parte B. Contabilidad 20X1'!A4:A247,"="&'Parte B. Asiento reg.'!A12,'Parte B. Contabilidad 20X1'!D4:D247) -> 700
A13: 631 | B13: Otros tributos | C13: =SUMIF('Parte B. Contabilidad 20X1'!A6:A254,"="&A13,'Parte B. Contabilidad 20X1'!C6:C254)-SUMIF('Parte B. Contabilidad 20X1'!A5:A248,"="&'Parte B. Asiento reg.'!A13,'Parte B. Contabilidad 20X1'!D5:D248) -> 25000
A14: 640 | B14: Sueldos y salarios | C14: =SUMIF('Parte B. Contabilidad 20X1'!A7:A255,"="&A14,'Parte B. Contabilidad 20X1'!C7:C255)-SUMIF('Parte B. Contabilidad 20X1'!A6:A249,"="&'Parte B. Asiento reg.'!A14,'Parte B. Contabilidad 20X1'!D6:D249) -> 102000
A15: 642 | B15: Seguridad Social a cargo de la empresa | C15: =SUMIF('Parte B. Contabilidad 20X1'!A8:A256,"="&A15,'Parte B. Contabilidad 20X1'!C8:C256)-SUMIF('Parte B. Contabilidad 20X1'!A7:A250,"="&'Parte B. Asiento reg.'!A15,'Parte B. Contabilidad 20X1'!D7:D250) -> 30000
A16: 650 | B16: Pérdidas de créditos comerciales incobrables | C16: =SUMIF('Parte B. Contabilidad 20X1'!A9:A257,"="&A16,'Parte B. Contabilidad 20X1'!C9:C257)-SUMIF('Parte B. Contabilidad 20X1'!A8:A251,"="&'Parte B. Asiento reg.'!A16,'Parte B. Contabilidad 20X1'!D8:D251) -> 35000
A17: 662 | B17: Intereses de deuda | C17: =SUMIF('Parte B. Contabilidad 20X1'!A10:A258,"="&A17,'Parte B. Contabilidad 20X1'!C10:C258)-SUMIF('Parte B. Contabilidad 20X1'!A9:A252,"="&'Parte B. Asiento reg.'!A17,'Parte B. Contabilidad 20X1'!D9:D252) -> 10000
A18: 665 | B18: Intereses por descuento de efectos y factoring | C18: =SUMIF('Parte B. Contabilidad 20X1'!A11:A259,"="&A18,'Parte B. Contabilidad 20X1'!C11:C259)-SUMIF('Parte B. Contabilidad 20X1'!A10:A253,"="&'Parte B. Asiento reg.'!A18,'Parte B. Contabilidad 20X1'!D10:D253) -> 64.4325
A19: 681 | B19: Amortización del inmovilizado material | C19: =SUMIF('Parte B. Contabilidad 20X1'!A12:A260,"="&A19,'Parte B. Contabilidad 20X1'!C12:C260)-SUMIF('Parte B. Contabilidad 20X1'!A11:A254,"="&'Parte B. Asiento reg.'!A19,'Parte B. Contabilidad 20X1'!D11:D254) -> 16000
A20: 693 | B20: Pérdidas por deterioro de existencias | C20: =SUMIF('Parte B. Contabilidad 20X1'!A13:A261,"="&A20,'Parte B. Contabilidad 20X1'!C13:C261)-SUMIF('Parte B. Contabilidad 20X1'!A12:A255,"="&'Parte B. Asiento reg.'!A20,'Parte B. Contabilidad 20X1'!D12:D255) -> 1755
A21: Total | C21: =SUM(C8:C20) -> 362079.43
A22: Resultado antes de impuestos | C22: =C6-C21 -> 1683020.6
A25: Código | B25: Cuenta | C25: Debe | D25: Haber
A26: 700 | B26: Venta de mercaderías | C26: =SUMIF('Parte B. Contabilidad 20X1'!A24:A267,"="&A26,'Parte B. Contabilidad 20X1'!D24:D267) -> 2007100
A27: 769 | B27: Otros ingresos financieros | C27: =SUMIF('Parte B. Contabilidad 20X1'!A25:A268,"="&A27,'Parte B. Contabilidad 20X1'!D25:D268) -> 1000
A28: 771 | B28: Beneficios procedentes del Inmovilizado material | C28: =SUMIF('Parte B. Contabilidad 20X1'!A26:A269,"="&A28,'Parte B. Contabilidad 20X1'!D26:D269) -> 37000
A29: 610 | B29: Variación de existencias de mercaderías | C29: =SUMIF('Parte B. Contabilidad 20X1'!A22:A270,"="&A29,'Parte B. Contabilidad 20X1'!C22:C270)-SUMIF('Parte B. Contabilidad 20X1'!A21:A264,"="&'Parte B. Asiento reg.'!A29,'Parte B. Contabilidad 20X1'!D21:D264) -> -4570
A30: 623 | B30: Servicios de profesionales independientes | D30: =SUMIF('Parte B. Contabilidad 20X1'!A23:A271,"="&A30,'Parte B. Contabilidad 20X1'!C23:C271)-SUMIF('Parte B. Contabilidad 20X1'!A22:A265,"="&'Parte B. Asiento reg.'!A30,'Parte B. Contabilidad 20X1'!D22:D265) -> 6000
A31: 626 | B31: Servicios bancarios y similares | D31: =SUMIF('Parte B. Contabilidad 20X1'!A24:A272,"="&A31,'Parte B. Contabilidad 20X1'!C24:C272)-SUMIF('Parte B. Contabilidad 20X1'!A23:A266,"="&'Parte B. Asiento reg.'!A31,'Parte B. Contabilidad 20X1'!D23:D266) -> 280
A32: 628 | B32: Suministros | D32: =SUMIF('Parte B. Contabilidad 20X1'!A25:A273,"="&A32,'Parte B. Contabilidad 20X1'!C25:C273)-SUMIF('Parte B. Contabilidad 20X1'!A24:A267,"="&'Parte B. Asiento reg.'!A32,'Parte B. Contabilidad 20X1'!D24:D267) -> 700
A33: 631 | B33: Otros tributos | D33: =SUMIF('Parte B. Contabilidad 20X1'!A26:A274,"="&A33,'Parte B. Contabilidad 20X1'!C26:C274)-SUMIF('Parte B. Contabilidad 20X1'!A25:A268,"="&'Parte B. Asiento reg.'!A33,'Parte B. Contabilidad 20X1'!D25:D268) -> 25000
A34: 640 | B34: Sueldos y salarios | D34: =SUMIF('Parte B. Contabilidad 20X1'!A27:A275,"="&A34,'Parte B. Contabilidad 20X1'!C27:C275)-SUMIF('Parte B. Contabilidad 20X1'!A26:A269,"="&'Parte B. Asiento reg.'!A34,'Parte B. Contabilidad 20X1'!D26:D269) -> 102000
A35: 642 | B35: Seguridad Social a cargo de la empresa | D35: =SUMIF('Parte B. Contabilidad 20X1'!A28:A276,"="&A35,'Parte B. Contabilidad 20X1'!C28:C276)-SUMIF('Parte B. Contabilidad 20X1'!A27:A270,"="&'Parte B. Asiento reg.'!A35,'Parte B. Contabilidad 20X1'!D27:D270) -> 30000
A36: 650 | B36: Pérdidas de créditos comerciales incobrables | D36: =SUMIF('Parte B. Contabilidad 20X1'!A29:A277,"="&A36,'Parte B. Contabilidad 20X1'!C29:C277)-SUMIF('Parte B. Contabilidad 20X1'!A28:A271,"="&'Parte B. Asiento reg.'!A36,'Parte B. Contabilidad 20X1'!D28:D271) -> 35000
A37: 662 | B37: Intereses de deuda | D37: =SUMIF('Parte B. Contabilidad 20X1'!A30:A278,"="&A37,'Parte B. Contabilidad 20X1'!C30:C278)-SUMIF('Parte B. Contabilidad 20X1'!A29:A272,"="&'Parte B. Asiento reg.'!A37,'Parte B. Contabilidad 20X1'!D29:D272) -> 10000
A38: 665 | B38: Intereses por descuento de efectos y factoring | D38: =SUMIF('Parte B. Contabilidad 20X1'!A31:A279,"="&A38,'Parte B. Contabilidad 20X1'!C31:C279)-SUMIF('Parte B. Contabilidad 20X1'!A30:A273,"="&'Parte B. Asiento reg.'!A38,'Parte B. Contabilidad 20X1'!D30:D273) -> 64.4325
A39: 681 | B39: Amortización del inmovilizado material | D39: =SUMIF('Parte B. Contabilidad 20X1'!A32:A280,"="&A39,'Parte B. Contabilidad 20X1'!C32:C280)-SUMIF('Parte B. Contabilidad 20X1'!A31:A274,"="&'Parte B. Asiento reg.'!A39,'Parte B. Contabilidad 20X1'!D31:D274) -> 16000
A40: 693 | B40: Pérdidas por deterioro de existencias | D40: =SUMIF('Parte B. Contabilidad 20X1'!A33:A281,"="&A40,'Parte B. Contabilidad 20X1'!C33:C281)-SUMIF('Parte B. Contabilidad 20X1'!A32:A275,"="&'Parte B. Asiento reg.'!A40,'Parte B. Contabilidad 20X1'!D32:D275) -> 1755
A41: 129 | B41: Pérdidas y ganancias | D41: =C22 -> 1683020.6
